Workbook

Sheet UAT
C1: https://www.jnjmedtech.com/
A2: From | B2: To | C2: New Destination | D2: Anchor Text | E2: Alt Text | F2: Status Code | G2: Status | H2: Path Type | I2: Link Path | J2: Link Position | K2: Link Origin
A3: https://jnj-uat.lower.jnj.brightspot.cloud/latest-news | B3: https://thenext.jnjmedtech.com/medtech-insights/post/what-roles-do-pfa-and-rfa-play-in-the-treatment-of-afib | C3: =IFERROR(XLOOKUP(B3,'Deduped URLs'!A:A,'Deduped URLs'!B:B,""),"") | E3: Surgeon using AI in surgery for advanced medical procedures | F3: 301 | G3: Moved Permanently | H3: Absolute | I3: //body/div[@id='main']/main/bsp-listcarousel/div[@class='PageList-items-wrap']/div[1]/div/div/div[5]/bsp-pagepromo/div[@class='PagePromo-media']/a | J3: Content | K3: HTML & Rendered HTML
A4: https://jnj-uat.lower.jnj.brightspot.cloud/latest-news | B4: https://thenext.jnjmedtech.com/medtech-insights/post/what-roles-do-pfa-and-rfa-play-in-the-treatment-of-afib | C4: =IFERROR(XLOOKUP(B4,'Deduped URLs'!A:A,'Deduped URLs'!B:B,""),"") | D4: An electrophysiologist discusses the role of cardiac ablation in the treatment of AFib | F4: 301 | G4: Moved Permanently | H4: Absolute | I4: //body/div[@id='main']/main/bsp-listcarousel/div[@class='PageList-items-wrap']/div[1]/div/div/div[5]/bsp-pagepromo/div[@class='PagePromo-content']/h3/a | J4: Content | K4: HTML & Rendered HTML
A5: https://jnj-uat.lower.jnj.brightspot.cloud/latest-news | B5: https://thenext.jnjmedtech.com/medtech-insights/post/what-roles-do-pfa-and-rfa-play-in-the-treatment-of-afib | C5: =IFERROR(XLOOKUP(B5,'Deduped URLs'!A:A,'Deduped URLs'!B:B,""),"") | D5: Read more | F5: 301 | G5: Moved Permanently | H5: Absolute | I5: //body/div[@id='main']/main/bsp-listcarousel/div[@class='PageList-items-wrap']/div[1]/div/div/div[5]/bsp-pagepromo/div[@class='PagePromo-content']/div[@class='PagePromo-ctaLink']/a | J5: Content | K5: HTML & Rendered HTML
A6: https://jnj-uat.lower.jnj.brightspot.cloud/latest-news | B6: https://thenext.jnjmedtech.com/medtech-insights/post/firing-up-the-next-step-in-surgical-stapling | C6: =IFERROR(XLOOKUP(B6,'Deduped URLs'!A:A,'Deduped URLs'!B:B,""),"") | D6: Firing up the next step in surgical stapling | F6: 301 | G6: Moved Permanently | H6: Absolute | I6: //body/div[@id='main']/main/bsp-pagepromo[@id='the-future-of-knee-replacement-surgery']/div/div[@class='PagePromoModuleC-CallOutA-contentWrap']/div/h3/a | J6: Content | K6: HTML & Rendered HTML
A7: https://jnj-uat.lower.jnj.brightspot.cloud/latest-news | B7: https://thenext.jnjmedtech.com/medtech-insights/post/firing-up-the-next-step-in-surgical-stapling | C7: =IFERROR(XLOOKUP(B7,'Deduped URLs'!A:A,'Deduped URLs'!B:B,""),"") | D7: Learn more | F7: 301 | G7: Moved Permanently | H7: Absolute | I7: //body/div[@id='main']/main/bsp-pagepromo[@id='the-future-of-knee-replacement-surgery']/div/div[@class='PagePromoModuleC-CallOutA-contentWrap']/div/div/a | J7: Content | K7: HTML & Rendered HTML
A8: https://jnj-uat.lower.jnj.brightspot.cloud/latest-news | B8: https://thenext.jnjmedtech.com/medtech-insights/post/firing-up-the-next-step-in-surgical-stapling | C8: =IFERROR(XLOOKUP(B8,'Deduped URLs'!A:A,'Deduped URLs'!B:B,""),"") | E8: A surgeon using a surgical stapler | F8: 301 | G8: Moved Permanently | H8: Absolute | I8: //body/div[@id='main']/main/bsp-pagepromo[@id='the-future-of-knee-replacement-surgery']/div/div[@class='PagePromo-media']/a | J8: Content | K8: HTML & Rendered HTML
A9: https://jnj-uat.lower.jnj.brightspot.cloud/future-of-surgery | B9: https://thenext.jnjmedtech.com/medtech-insights/post/firing-up-the-next-step-in-surgical-stapling | C9: =IFERROR(XLOOKUP(B9,'Deduped URLs'!A:A,'Deduped URLs'!B:B,""),"") | E9: Future of Surgery Landing Page Alt.png | F9: 301 | G9: Moved Permanently | H9: Absolute | I9: //body/div[@id='main']/main/bsp-list-loadmore[@id='list-module-900000']/div/div[2]/bsp-pagepromo/div[@class='PagePromo-media']/a | J9: Content | K9: HTML & Rendered HTML
A10: https://jnj-uat.lower.jnj.brightspot.cloud/future-of-surgery | B10: https://thenext.jnjmedtech.com/medtech-insights/post/firing-up-the-next-step-in-surgical-stapling | C10: =IFERROR(XLOOKUP(B10,'Deduped URLs'!A:A,'Deduped URLs'!B:B,""),"") | D10: Firing up the next step in surgical stapling | F10: 301 | G10: Moved Permanently | H10: Absolute | I10: //body/div[@id='main']/main/bsp-list-loadmore[@id='list-module-900000']/div/div[2]/bsp-pagepromo/div[@class='PagePromo-content']/h2/a | J10: Content | K10: HTML & Rendered HTML
A11: https://jnj-uat.lower.jnj.brightspot.cloud/future-of-surgery | B11: https://thenext.jnjmedtech.com/medtech-insights/post/firing-up-the-next-step-in-surgical-stapling | C11: =IFERROR(XLOOKUP(B11,'Deduped URLs'!A:A,'Deduped URLs'!B:B,""),"") | D11: Read more | F11: 301 | G11: Moved Permanently | H11: Absolute | I11: //body/div[@id='main']/main/bsp-list-loadmore[@id='list-module-900000']/div/div[2]/bsp-pagepromo/div[@class='PagePromo-content']/div[@class='PagePromo-ctaLink']/a | J11: Content | K11: HTML & Rendered HTML
A12: https://jnj-uat.lower.jnj.brightspot.cloud/CH/latest-news/relier-industrie-et-universite-faconner-la-prochaine-generation-dinnovateurs-en-sante | B12: https://thenext.jnjmedtech.com/ | C12: https://www.jnjmedtech.com/ | D12: J&J MedTech | F12: 301 | G12: Moved Permanently | H12: Absolute | I12: //body/bsp-header/div[@class='Page-header-topNav-container']/nav/ul/li[1]/ul/li[@class='GlobalSiteNavigation-items-item'][3]/div/div/a | J12: Navigation | K12: HTML & Rendered HTML
A13: https://jnj-uat.lower.jnj.brightspot.cloud/CH/latest-news/relier-industrie-et-universite-faconner-la-prochaine-generation-dinnovateurs-en-sante | B13: https://thenext.jnjmedtech.com/ | C13: https://www.jnjmedtech.com/ | D13: J&J MedTech | F13: 301 | G13: Moved Permanently | H13: Absolute | I13: //body/bsp-header/div[@class='Page-header-topNav-container']/nav/ul/li[1]/div/ul/li[@class='GlobalSiteNavigation-items-item'][3]/div/div/a | J13: Navigation | K13: HTML & Rendered HTML
A14: https://jnj-uat.lower.jnj.brightspot.cloud/CH/de/nics-story | B14: https://thenext.jnjmedtech.com/ | C14: https://www.jnjmedtech.com/ | D14: J&J MedTech | F14: 301 | G14: Moved Permanently | H14: Absolute | I14: //body/bsp-header/div[@class='Page-header-topNav-container']/nav/ul/li[1]/ul/li[@class='GlobalSiteNavigation-items-item'][3]/div/div/a | J14: Navigation | K14: HTML & Rendered HTML
A15: https://jnj-uat.lower.jnj.brightspot.cloud/CH/de/nics-story | B15: https://thenext.jnjmedtech.com/ | C15: https://www.jnjmedtech.com/ | D15: J&J MedTech | F15: 301 | G15: Moved Permanently | H15: Absolute | I15: //body/bsp-header/div[@class='Page-header-topNav-container']/nav/ul/li[1]/div/ul/li[@class='GlobalSiteNavigation-items-item'][3]/div/div/a | J15: Navigation | K15: HTML & Rendered HTML
A16: https://jnj-uat.lower.jnj.brightspot.cloud/CH/de/zoes-story | B16: https://thenext.jnjmedtech.com/ | C16: https://www.jnjmedtech.com/ | D16: J&J MedTech | F16: 301 | G16: Moved Permanently | H16: Absolute | I16: //body/bsp-header/div[@class='Page-header-topNav-container']/nav/ul/li[1]/ul/li[@class='GlobalSiteNavigation-items-item'][3]/div/div/a | J16: Navigation | K16: HTML & Rendered HTML
A17: https://jnj-uat.lower.jnj.brightspot.cloud/CH/de/zoes-story | B17: https://thenext.jnjmedtech.com/ | C17: https://www.jnjmedtech.com/ | D17: J&J MedTech | F17: 301 | G17: Moved Permanently | H17: Absolute | I17: //body/bsp-header/div[@class='Page-header-topNav-container']/nav/ul/li[1]/div/ul/li[@class='GlobalSiteNavigation-items-item'][3]/div/div/a | J17: Navigation | K17: HTML & Rendered HTML
A18: https://jnj-uat.lower.jnj.brightspot.cloud/CH/de/data-privacy | B18: https://thenext.jnjmedtech.com/ | C18: https://www.jnjmedtech.com/ | D18: J&J MedTech | F18: 301 | G18: Moved Permanently | H18: Absolute | I18: //body/bsp-header/div[@class='Page-header-topNav-container']/nav/ul/li[1]/ul/li[@class='GlobalSiteNavigation-items-item'][3]/div/div/a | J18: Navigation | K18: HTML & Rendered HTML
A19: https://jnj-uat.lower.jnj.brightspot.cloud/CH/de/data-privacy | B19: https://thenext.jnjmedtech.com/ | C19: https://www.jnjmedtech.com/ | D19: J&J MedTech | F19: 301 | G19: Moved Permanently | H19: Absolute | I19: //body/bsp-header/div[@class='Page-header-topNav-container']/nav/ul/li[1]/div/ul/li[@class='GlobalSiteNavigation-items-item'][3]/div/div/a | J19: Navigation | K19: HTML & Rendered HTML
A20: https://jnj-uat.lower.jnj.brightspot.cloud/privacy-center/en-us/privacy-statement?s=00000195-202e-ddef-a3f7-213f11db0000&p=00000195-202a-ddef-a3f7-213b3e7b0000 | B20: https://thenext.jnjmedtech.com/ | C20: =IFERROR(XLOOKUP(B20,'Deduped URLs'!A:A,'Deduped URLs'!B:B,""),"") | D20: Medical devices & technology | F20: 301 | G20: Moved Permanently | H20: Absolute | I20: //body/bsp-header/div[@class='Page-header-topNav-container']/nav/ul/li[1]/ul/li[@class='GlobalSiteNavigation-items-item'][3]/div/div/a | J20: Navigation | K20: HTML & Rendered HTML
A21: https://jnj-uat.lower.jnj.brightspot.cloud/privacy-center/en-us/privacy-statement?s=00000195-202e-ddef-a3f7-213f11db0000&p=00000195-202a-ddef-a3f7-213b3e7b0000 | B21: https://thenext.jnjmedtech.com/ | C21: =IFERROR(XLOOKUP(B21,'Deduped URLs'!A:A,'Deduped URLs'!B:B,""),"") | D21: Medical devices & technology | F21: 301 | G21: Moved Permanently | H21: Absolute | I21: //body/bsp-header/div[@class='Page-header-topNav-container']/nav/ul/li[1]/div/ul/li[@class='GlobalSiteNavigation-items-item'][3]/div/div/a | J21: Navigation | K21: HTML & Rendered HTML
A22: https://jnj-uat.lower.jnj.brightspot.cloud/privacy-center/en-us/privacy-statement?s=00000195-202e-ddef-a3f7-213f11db0000&p=00000195-202a-ddef-a3f7-213b3e7b0000 | B22: https://thenext.jnjmedtech.com/ | C22: =IFERROR(XLOOKUP(B22,'Deduped URLs'!A:A,'Deduped URLs'!B:B,""),"") | D22: Medical devices & technology | F22: 301 | G22: Moved Permanently | H22: Absolute | I22: //body/footer/div/div[@class='Page-footer-columns']/div/div/bsp-footer-nav/ul/li[@class='FooterNavigation-items-item'][1]/div/ul/li[@class='FooterNavigationItem-items-item'][3]/a | J22: Navigation | K22: HTML & Rendered HTML
A23: https://jnj-uat.lower.jnj.brightspot.cloud/CH/fr | B23: https://thenext.jnjmedtech.com/ | C23: https://www.jnjmedtech.com/ | D23: J&J MedTech | F23: 301 | G23: Moved Permanently | H23: Absolute | I23: //body/bsp-header/div[@class='Page-header-topNav-container']/nav/ul/li[1]/ul/li[@class='GlobalSiteNavigation-items-item'][3]/div/div/a | J23: Navigation | K23: HTML & Rendered HTML
A24: https://jnj-uat.lower.jnj.brightspot.cloud/CH/fr | B24: https://thenext.jnjmedtech.com/ | C24: https://www.jnjmedtech.com/ | D24: J&J MedTech | F24: 301 | G24: Moved Permanently | H24: Absolute | I24: //body/bsp-header/div[@class='Page-header-topNav-container']/nav/ul/li[1]/div/ul/li[@class='GlobalSiteNavigation-items-item'][3]/div/div/a | J24: Navigation | K24: HTML & Rendered HTML
A25: https://jnj-uat.lower.jnj.brightspot.cloud/CH/de | B25: https://thenext.jnjmedtech.com/ | C25: https://www.jnjmedtech.com/ | D25: J&J MedTech | F25: 301 | G25: Moved Permanently | H25: Absolute | I25: //body/bsp-header/div[@class='Page-header-topNav-container']/nav/ul/li[1]/ul/li[@class='GlobalSiteNavigation-items-item'][3]/div/div/a | J25: Navigation | K25: HTML & Rendered HTML
A26: https://jnj-uat.lower.jnj.brightspot.cloud/CH/de | B26: https://thenext.jnjmedtech.com/ | C26: https://www.jnjmedtech.com/ | D26: J&J MedTech | F26: 301 | G26: Moved Permanently | H26: Absolute | I26: //body/bsp-header/div[@class='Page-header-topNav-container']/nav/ul/li[1]/div/ul/li[@class='GlobalSiteNavigation-items-item'][3]/div/div/a | J26: Navigation | K26: HTML & Rendered HTML
A27: https://jnj-uat.lower.jnj.brightspot.cloud/CH/ | B27: https://thenext.jnjmedtech.com/ | C27: https://www.jnjmedtech.com/ | D27: J&J MedTech | F27: 301 | G27: Moved Permanently | H27: Absolute | I27: //body/bsp-header/div[@class='Page-header-topNav-container']/nav/ul/li[1]/ul/li[@class='GlobalSiteNavigation-items-item'][3]/div/div/a | J27: Navigation | K27: HTML & Rendered HTML
A28: https://jnj-uat.lower.jnj.brightspot.cloud/CH/ | B28: https://thenext.jnjmedtech.com/ | C28: https://www.jnjmedtech.com/ | D28: J&J MedTech | F28: 301 | G28: Moved Permanently | H28: Absolute | I28: //body/bsp-header/div[@class='Page-header-topNav-container']/nav/ul/li[1]/div/ul/li[@class='GlobalSiteNavigation-items-item'][3]/div/div/a | J28: Navigation | K28: HTML & Rendered HTML
A29: https://jnj-uat.lower.jnj.brightspot.cloud/innovativemedicine/argentina/ | B29: https://thenext.jnjmedtech.com/ | C29: https://www.jnjmedtech.com/ | D29: Medical devices & technology | F29: 301 | G29: Moved Permanently | H29: Absolute | I29: //body/bsp-header/div[@class='Page-header-topNav-container']/nav/ul/li[1]/ul/li[@class='GlobalSiteNavigation-items-item'][3]/div/div/a | J29: Navigation | K29: HTML & Rendered HTML
A30: https://jnj-uat.lower.jnj.brightspot.cloud/innovativemedicine/argentina/ | B30: https://thenext.jnjmedtech.com/ | C30: https://www.jnjmedtech.com/ | D30: Medical devices & technology | F30: 301 | G30: Moved Permanently | H30: Absolute | I30: //body/bsp-header/div[@class='Page-header-topNav-container']/nav/ul/li[1]/div/ul/li[@class='GlobalSiteNavigation-items-item'][3]/div/div/a | J30: Navigation | K30: HTML & Rendered HTML
A31: https://jnj-uat.lower.jnj.brightspot.cloud/innovativemedicine/apac/ | B31: https://thenext.jnjmedtech.com/ | C31: https://www.jnjmedtech.com/ | D31: Medical devices & technology | F31: 301 | G31: Moved Permanently | H31: Absolute | I31: //body/bsp-header/div[@class='Page-header-topNav-container']/nav/ul/li[1]/ul/li[@class='GlobalSiteNavigation-items-item'][3]/div/div/a | J31: Navigation | K31: HTML & Rendered HTML
A32: https://jnj-uat.lower.jnj.brightspot.cloud/innovativemedicine/apac/ | B32: https://thenext.jnjmedtech.com/ | C32: https://www.jnjmedtech.com/ | D32: Medical devices & technology | F32: 301 | G32: Moved Permanently | H32: Absolute | I32: //body/bsp-header/div[@class='Page-header-topNav-container']/nav/ul/li[1]/div/ul/li[@class='GlobalSiteNavigation-items-item'][3]/div/div/a | J32: Navigation | K32: HTML & Rendered HTML
A33: https://jnj-uat.lower.jnj.brightspot.cloud/privacy-center/en-us/privacy-statement?s=00000195-202e-ddef-a3f7-213fc5d00000&p=00000195-202a-ddef-a3f7-213b3e7b0000 | B33: https://thenext.jnjmedtech.com/ | C33: =IFERROR(XLOOKUP(B33,'Deduped URLs'!A:A,'Deduped URLs'!B:B,""),"") | D33: Medical devices & technology | F33: 301 | G33: Moved Permanently | H33: Absolute | I33: //body/bsp-header/div[@class='Page-header-topNav-container']/nav/ul/li[1]/ul/li[@class='GlobalSiteNavigation-items-item'][3]/div/div/a | J33: Navigation | K33: HTML & Rendered HTML
A34: https://jnj-uat.lower.jnj.brightspot.cloud/privacy-center/en-us/privacy-statement?s=00000195-202e-ddef-a3f7-213fc5d00000&p=00000195-202a-ddef-a3f7-213b3e7b0000 | B34: https://thenext.jnjmedtech.com/ | C34: =IFERROR(XLOOKUP(B34,'Deduped URLs'!A:A,'Deduped URLs'!B:B,""),"") | D34: Medical devices & technology | F34: 301 | G34: Moved Permanently | H34: Absolute | I34: //body/bsp-header/div[@class='Page-header-topNav-container']/nav/ul/li[1]/div/ul/li[@class='GlobalSiteNavigation-items-item'][3]/div/div/a | J34: Navigation | K34: HTML & Rendered HTML
A35: https://jnj-uat.lower.jnj.brightspot.cloud/privacy-center/en-us/privacy-statement?s=00000195-202e-ddef-a3f7-213fc5d00000&p=00000195-202a-ddef-a3f7-213b3e7b0000 | B35: https://thenext.jnjmedtech.com/ | C35: =IFERROR(XLOOKUP(B35,'Deduped URLs'!A:A,'Deduped URLs'!B:B,""),"") | D35: Medical devices & technology | F35: 301 | G35: Moved Permanently | H35: Absolute | I35: //body/footer/div/div[@class='Page-footer-columns']/div/div/bsp-footer-nav/ul/li[@class='FooterNavigation-items-item'][1]/div/ul/li[@class='FooterNavigationItem-items-item'][3]/a | J35: Navigation | K35: HTML & Rendered HTML
A36: https://jnj-uat.lower.jnj.brightspot.cloud/innovativemedicine/belgium/fr | B36: https://thenext.jnjmedtech.com/ | C36: https://www.jnjmedtech.com/ | D36: Medical devices & technology | F36: 301 | G36: Moved Permanently | H36: Absolute | I36: //body/bsp-header/div[@class='Page-header-topNav-container']/nav/ul/li[1]/ul/li[@class='GlobalSiteNavigation-items-item'][3]/div/div/a | J36: Navigation | K36: HTML & Rendered HTML
A37: https://jnj-uat.lower.jnj.brightspot.cloud/innovativemedicine/belgium/fr | B37: https://thenext.jnjmedtech.com/ | C37: https://www.jnjmedtech.com/ | D37: Medical devices & technology | F37: 301 | G37: Moved Permanently | H37: Absolute | I37: //body/bsp-header/div[@class='Page-header-topNav-container']/nav/ul/li[1]/div/ul/li[@class='GlobalSiteNavigation-items-item'][3]/div/div/a | J37: Navigation | K37: HTML & Rendered HTML
A38: https://jnj-uat.lower.jnj.brightspot.cloud/innovativemedicine/belgium/nl | B38: https://thenext.jnjmedtech.com/ | C38: https://www.jnjmedtech.com/ | D38: Medical devices & technology | F38: 301 | G38: Moved Permanently | H38: Absolute | I38: //body/bsp-header/div[@class='Page-header-topNav-container']/nav/ul/li[1]/ul/li[@class='GlobalSiteNavigation-items-item'][3]/div/div/a | J38: Navigation | K38: HTML & Rendered HTML
A39: https://jnj-uat.lower.jnj.brightspot.cloud/innovativemedicine/belgium/nl | B39: https://thenext.jnjmedtech.com/ | C39: https://www.jnjmedtech.com/ | D39: Medical devices & technology | F39: 301 | G39: Moved Permanently | H39: Absolute | I39: //body/bsp-header/div[@class='Page-header-topNav-container']/nav/ul/li[1]/div/ul/li[@class='GlobalSiteNavigation-items-item'][3]/div/div/a | J39: Navigation | K39: HTML & Rendered HTML
A40: https://jnj-uat.lower.jnj.brightspot.cloud/innovativemedicine/sweden/ | B40: https://thenext.jnjmedtech.com/ | C40: https://www.jnjmedtech.com/ | D40: Medical devices & technology | F40: 301 | G40: Moved Permanently | H40: Absolute | I40: //body/bsp-header/div[@class='Page-header-topNav-container']/nav/ul/li[1]/ul/li[@class='GlobalSiteNavigation-items-item'][3]/div/div/a | J40: Navigation | K40: HTML & Rendered HTML
...
